File: test2_sample_e_Group_6
%	Crosshead Position (in)	Load (lbs)	Extensometer Position (in)	3/6/2017	3:41 PM
-0.00015501	-1.40696418	-0.00699924
0.00032977	44.37967300	-0.00697285
0.00083429	98.77291107	-0.00692944
0.00133878	154.58918762	-0.00689636
0.00183840	206.29579163	-0.00685744
0.00234536	243.50263977	-0.00684389
0.00284003	269.81152344	-0.00684232
0.00333227	293.93090820	-0.00682339
0.00382695	316.54150391	-0.00681190
0.00432900	341.99414062	-0.00679883
0.00484091	363.41351318	-0.00677235
0.00534296	382.21456909	-0.00675544
0.00584254	400.73959351	-0.00672649
0.00633969	416.54180908	-0.00670776
0.00683683	431.22515869	-0.00668401
0.00733151	447.73489380	-0.00665636
0.00783356	463.01986694	-0.00663184
0.00833561	478.37991333	-0.00661053
0.00883766	496.04064941	-0.00659451
0.00934219	511.75979614	-0.00658156
0.00984424	526.56909180	-0.00656286
0.01034135	543.89349365	-0.00655571
0.01083602	559.62603760	-0.00654180
0.01132827	572.78454590	-0.00653562
0.01183032	593.30206299	-0.00652064
0.01233975	610.61712646	-0.00650273
0.01284180	624.06103516	-0.00648361
0.01334385	645.80731201	-0.00647157
0.01384348	662.45904541	-0.00645386
0.01433815	676.26470947	-0.00643881
0.01483282	688.63665771	-0.00643696
0.01532993	711.25524902	-0.00641252
0.01583693	723.00543213	-0.00639379
0.01633898	743.75347900	-0.00639394
0.01684104	757.72662354	-0.00637230
0.01734804	776.65362549	-0.00635315
0.01784024	789.67272949	-0.00635524
0.01833243	811.58251953	-0.00632089
0.01882958	831.45690918	-0.00631988
0.01932916	846.79150391	-0.00630572
0.01984107	864.34100342	-0.00629477
0.02034312	877.64288330	-0.00626613
0.02084274	902.87042236	-0.00625765
0.02134232	920.25378418	-0.00624071
0.02183699	934.10369873	-0.00621818
0.02233414	952.93420410	-0.00621137
0.02283129	966.90869141	-0.00619322
0.02333577	985.10144043	-0.00617382
0.02383783	1000.35559082	-0.00616553
0.02434235	999.30908203	-0.00616682
0.02484440	1034.11340332	-0.00613165
0.02534155	1042.05664062	-0.00612229
0.02583375	1066.17736816	-0.00610536
0.02632843	1080.19616699	-0.00609334
0.02683048	1103.74340820	-0.00606787
0.02733996	1121.68823242	-0.00605513
0.02784201	1129.27368164	-0.00604203
0.02834406	1155.18469238	-0.00601828
0.02884364	1173.32641602	-0.00601590
0.02933831	1183.64282227	-0.00599585
0.02983299	1207.06140137	-0.00598785
0.03033013	1226.17333984	-0.00595656
0.03083709	1234.27478027	-0.00595249
0.03133919	1261.13574219	-0.00593555
0.03184124	1281.40136719	-0.00590461
0.03234329	1290.70751953	-0.00589924
0.03284040	1315.12963867	-0.00589128
0.03333264	1329.08410645	-0.00586702
0.03382731	1345.58581543	-0.00584845
0.03432937	1353.82385254	-0.00584899
0.03483880	1384.84948730	-0.00581729
0.03534085	1403.29003906	-0.00579616
0.03584290	1409.15783691	-0.00581215
0.03634253	1439.69689941	-0.00576448
0.03683720	1457.69799805	-0.00574316
0.03733430	1464.50109863	-0.00572711
0.03783145	1494.00842285	-0.00571227
0.03833350	1513.78906250	-0.00568856
0.03883803	1523.29345703	-0.00567432
0.03934008	1552.62927246	-0.00564951
0.03984461	1571.55761719	-0.00562325
0.04034419	1576.27160645	-0.00561462
0.04083396	1606.16223145	-0.00558707
0.04132863	1626.17065430	-0.00556524
0.04183068	1631.54785156	-0.00556225
0.04234011	1663.95092773	-0.00552200
0.04284464	1685.90368652	-0.00549023
0.04334179	1691.08264160	-0.00549079
0.04384137	1720.81506348	-0.00545952
0.04433852	1737.46948242	-0.00543645
0.04483319	1750.46313477	-0.00542052
0.04533034	1776.71716309	-0.00539178
0.04583482	1794.44494629	-0.00536388
0.04633935	1813.55017090	-0.00534293
0.04684388	1837.25683594	-0.00531723
0.04734102	1855.33032227	-0.00529045
0.04784060	1874.09643555	-0.00526750
0.04833528	1877.14221191	-0.00523965
0.04882995	1901.09143066	-0.00521578
0.04932953	1926.84692383	-0.00518022
0.04983653	1938.54479980	-0.00515947
0.05034348	1957.75720215	-0.00513460
0.05084311	1984.98535156	-0.00509439
0.05134268	1999.15417480	-0.00506781
0.05183984	2022.58081055	-0.00502726
0.05233451	2041.77050781	-0.00499965
0.05283166	2054.57373047	-0.00496747
0.05333618	2074.16406250	-0.00493647
0.05383824	2101.35595703	-0.00488928
0.05434272	2117.90185547	-0.00485355
0.05484482	2131.25195312	-0.00482891
0.05534192	2142.75708008	-0.00476763
0.05583416	2162.63403320	-0.00473607
0.05632884	2183.68896484	-0.00469343
0.05682841	2209.09594727	-0.00464360
0.05734032	2229.59204102	-0.00459062
0.05784237	2245.17333984	-0.00454584
0.05834195	2258.06787109	-0.00450794
0.05884400	2273.73876953	-0.00445290
0.05933625	2286.23120117	-0.00440370
0.05983335	2313.45117187	-0.00433604
0.06033050	2322.75195312	-0.00428338
0.06083503	2344.15795898	-0.00422393
0.06133955	2362.04516602	-0.00415494
0.06183913	2381.43164062	-0.00407997
0.06234366	2395.76538086	-0.00401999
0.06284323	2410.42065430	-0.00394568
0.06333300	2413.94335937	-0.00387819
0.06382768	2442.85839844	-0.00378704
0.06432973	2456.53955078	-0.00370415
0.06483916	2466.95776367	-0.00361574
0.06534122	2487.17114258	-0.00351277
0.06584084	2491.71484375	-0.00343543
0.06634042	2504.84130859	-0.00334007
0.06683756	2522.58911133	-0.00320847
0.06733224	2534.14892578	-0.00310826
0.06782939	2547.72290039	-0.00298032
0.06833387	2545.04833984	-0.00288075
0.06883840	2569.95556641	-0.00274754
0.06934293	2578.37866211	-0.00263824
0.06984250	2592.37182617	-0.00247923
0.07033965	2593.75073242	-0.00235674
0.07083432	2606.79516602	-0.00219941
0.07132900	2617.65307617	-0.00203761
0.07182862	2617.18798828	-0.00192386
0.07234048	2634.29931641	-0.00176921
0.07284258	2642.98779297	-0.00159274
0.07334216	2650.73950195	-0.00139345
0.07384421	2657.91772461	-0.00120839
0.07433888	2664.70043945	-0.00102073
0.07483603	2671.59741211	-0.00082602
0.07533070	2676.77368164	-0.00064057
0.07583524	2672.40527344	-0.00052612
0.07633971	2687.53222656	-0.00036310
0.07683934	2683.05810547	-0.00027369
0.07734387	2691.55200195	-0.00013997
0.07784097	2702.05615234	0.00005144
0.07833564	2705.33105469	0.00025496
0.07883032	2709.68579102	0.00046554
0.07932746	2714.83666992	0.00066879
0.07983937	2720.01708984	0.00088242
0.08034389	2724.57812500	0.00110649
0.08084100	2729.02832031	0.00131933
0.08134553	2732.63940430	0.00152998
0.08183773	2735.79785156	0.00175676
0.08233488	2739.90332031	0.00197408
0.08283202	2742.58471680	0.00220765
0.08333407	2746.07519531	0.00241898
0.08384103	2750.56005859	0.00263989
0.08434065	2753.57373047	0.00286715
0.08484519	2757.14208984	0.00309950
0.08534229	2759.81274414	0.00332044
0.08583453	2761.00512695	0.00355496
0.08632920	2763.32055664	0.00378826
0.08682878	2766.47094727	0.00402056
0.08734069	2770.04736328	0.00424710
0.08784274	2773.54199219	0.00447768
0.08834232	2775.82128906	0.00471820
0.08884194	2776.47241211	0.00495106
0.08933909	2779.16699219	0.00518468
0.08983376	2781.50927734	0.00542964
0.09033334	2782.21826172	0.00565715
0.09083539	2784.78027344	0.00590143
0.09133744	2787.47216797	0.00614093
0.09184197	2789.78491211	0.00638278
0.09234402	2791.87402344	0.00662084
0.09284117	2792.96606445	0.00687215
0.09333337	2792.90039062	0.00711489
0.09382804	2793.95629883	0.00735453
0.09432767	2778.71289062	0.00745478
0.09484200	2797.32226562	0.00765359
0.09534406	2801.94116211	0.00787577
0.09584121	2802.21850586	0.00813425
0.09634326	2802.82153320	0.00837639
0.09683793	2803.87060547	0.00860503
0.09733508	2804.80468750	0.00885931
0.09783218	2804.79125977	0.00911042
0.09833428	2806.45947266	0.00935826
0.09883876	2808.87011719	0.00960916
0.09933838	2809.30834961	0.00988093
0.09984291	2810.87207031	0.01012596
0.10034249	2812.74267578	0.01035300
0.10083469	2811.50048828	0.01061648
0.10132936	2811.66796875	0.01086673
0.10182651	2813.62841797	0.01112181
0.10233842	2815.79248047	0.01139104
0.10284294	2817.14721680	0.01164013
0.10334253	2818.28881836	0.01190487
0.10384210	2818.61303711	0.01216680
0.10434172	2819.39160156	0.01242167
0.10483392	2819.89404297	0.01267853
0.10533107	2819.73852539	0.01292875
0.10583560	2821.14550781	0.01319286
0.10634008	2822.61962891	0.01345158
0.10684709	2823.96362305	0.01371348
0.10734423	2824.90942383	0.01397741
0.10784134	2825.34643555	0.01424301
0.10833358	2824.12426758	0.01450524
0.10882825	2824.01440430	0.01477212
0.10932783	2825.21240234	0.01502317
0.10983974	2827.09106445	0.01529172
0.11034426	2828.68554687	0.01554891
0.11084384	2829.19067383	0.01582476
0.11134099	2828.68969727	0.01610649
0.11184057	2828.85986328	0.01636407
0.11233281	2829.67309570	0.01663879
0.11283239	2829.61694336	0.01691476
0.11333444	2830.09521484	0.01716140
0.11383897	2831.82250977	0.01742691
0.11434102	2832.39599609	0.01769948
0.11484555	2832.98828125	0.01797858
0.11534023	2833.26147461	0.01825252
0.11583489	2832.23510742	0.01852354
0.11632957	2832.39331055	0.01879451
0.11682672	2832.52734375	0.01906899
0.11733858	2834.11914062	0.01932347
0.11784311	2835.59448242	0.01960722
0.11834516	2836.44921875	0.01988623
0.11884478	2835.91455078	0.02015677
0.11933945	2835.65869141	0.02043310
0.11983413	2836.06469727	0.02071083
0.12033371	2835.30224609	0.02098882
0.12083333	2836.26708984	0.02125475
0.12134028	2838.10156250	0.02153057
0.12184234	2837.51318359	0.02180716
0.12234686	2838.24609375	0.02209058
0.12284154	2839.26733398	0.02237383
0.12333374	2837.73974609	0.02264988
0.12382841	2837.30957031	0.02292943
0.12432803	2837.89379883	0.02318680
0.12483994	2839.46704102	0.02347451
0.12534443	2840.49462891	0.02375245
0.12584157	2840.37670898	0.02404058
0.12634610	2840.17163086	0.02431744
0.12684077	2840.39160156	0.02460986
0.12733544	2840.34863281	0.02489102
0.12783259	2839.29003906	0.02516419
0.12833217	2840.14233398	0.02544588
0.12883671	2841.31201172	0.02573812
0.12933876	2840.60327148	0.02603179
0.12984328	2841.89086914	0.02631044
0.13034038	2842.33300781	0.02658999
0.13083506	2841.05200195	0.02689192
0.13132730	2839.45751953	0.02714777
0.13182688	2840.77612305	0.02743793
0.13233878	2841.65234375	0.02772835
0.13284332	2843.21606445	0.02801996
0.13334289	2843.63696289	0.02831331
0.13384251	2842.70556641	0.02859679
0.13433962	2842.25415039	0.02890182
0.13483429	2842.03564453	0.02917683
0.13533144	2841.31347656	0.02946460
0.13583596	2842.38012695	0.02975261
0.13634050	2843.79907227	0.03005233
0.13684255	2843.03125000	0.03035009
0.13734460	2844.02270508	0.03063378
0.13784175	2844.01074219	0.03093493
0.13833642	2842.21508789	0.03122923
0.13882862	2841.94995117	0.03149185
0.13932820	2842.13891602	0.03179646
0.13983762	2843.01513672	0.03209740
0.14034463	2844.54272461	0.03238234
0.14083931	2844.45019531	0.03269318
0.14134383	2843.77099609	0.03299108
0.14183851	2843.48413086	0.03328747
0.14233318	2843.34350586	0.03357854
0.14283276	2843.16650391	0.03387979
0.14333238	2843.17065430	0.03417346
0.14383933	2844.54663086	0.03447700
0.14434138	2843.82592773	0.03477493
0.14484344	2844.42871094	0.03508142
0.14534307	2844.81347656	0.03536814
0.14583527	2843.40380859	0.03565708
0.14632994	2842.59985352	0.03596064
0.14682709	2842.33178711	0.03626531
0.14733651	2843.35693359	0.03657880
0.14784594	2845.03051758	0.03687751
0.14834061	2844.96484375	0.03717431
0.14884515	2844.07226562	0.03748581
0.14933982	2843.40112305	0.03778681
0.14983450	2843.81640625	0.03809294
0.15033165	2842.41625977	0.03839767
0.15083370	2843.20410156	0.03870460
0.15133822	2844.30957031	0.03901356
0.15184027	2843.66625977	0.03932425
0.15234476	2844.33642578	0.03963304
0.15283944	2843.91015625	0.03991690
0.15333411	2843.10498047	0.04023656
0.15382634	2841.95800781	0.04054606
0.15432593	2842.13354492	0.04084453
0.15483783	2843.70385742	0.04116720
0.15534236	2844.08300781	0.04147968
0.15584193	2844.07910156	0.04178876
0.15634400	2843.62622070	0.04209423
0.15683867	2843.01391602	0.04240513
0.15733333	2842.64404297	0.04272613
0.15783049	2841.50903320	0.04304573
0.15833254	2843.12377930	0.04335588
0.15883954	2843.91015625	0.04367092
0.15934159	2842.29565430	0.04398561
0.15984364	2843.38085937	0.04430616
0.16034323	2843.72924805	0.04458690
0.16083299	2841.65112305	0.04491919
0.16132766	2840.70629883	0.04523692
0.16182724	2840.90209961	0.04555053
0.16233668	2842.10131836	0.04586822
0.16284367	2842.66406250	0.04619482
0.16334082	2843.05004883	0.04651418
0.16384287	2842.32495117	0.04684955
0.16433997	2841.33886719	0.04716772
0.16483469	2841.03198242	0.04749179
0.16533180	2840.77612305	0.04780960
0.16583143	2840.73852539	0.04813024
0.16633838	2841.89233398	0.04847497
0.16684043	2841.06958008	0.04878229
0.16734248	2841.66040039	0.04911047
0.16784211	2841.47949219	0.04945102
0.16833921	2840.34985352	0.04977086
0.16882898	2839.59960937	0.05004954
0.16932613	2839.02880859	0.05038685
0.16983804	2839.66918945	0.05072281
0.17034009	2841.03466797	0.05105022
0.17084214	2841.27587891	0.05139029
0.17134419	2840.77343750	0.05172947
0.17183886	2840.14355469	0.05205593
0.17233354	2839.39599609	0.05239576
0.17282821	2837.95141602	0.05272916
0.17333518	2838.60253906	0.05306521
0.17383970	2840.20117187	0.05339000
0.17434175	2839.13720703	0.05373317
0.17484628	2839.68530273	0.05408630
0.17534095	2839.28881836	0.05440626
0.17583562	2838.19116211	0.05471352
0.17633030	2837.26269531	0.05505157
0.17682745	2837.41284180	0.05539471
0.17733936	2837.80126953	0.05574265
0.17784141	2838.90820312	0.05608994
0.17834346	2838.94702148	0.05643466
0.17884304	2838.27026367	0.05677497
0.17934018	2837.43017578	0.05712089
0.17983486	2836.88745117	0.05747011
0.18033201	2835.85839844	0.05781248
0.18083405	2835.91723633	0.05816254
0.18133859	2837.55737305	0.05845538
0.18184307	2836.89282227	0.05879918
0.18234269	2836.46801758	0.05915320
0.18284227	2837.20898437	0.05949423
0.18333451	2835.19506836	0.05985019
0.18382919	2834.78784180	0.06019339
0.18432629	2834.01733398	0.06056112
0.18483576	2834.86669922	0.06089956
0.18534273	2835.96166992	0.06126019
0.18583988	2835.49121094	0.06161866
0.18634440	2835.52343750	0.06196585
0.18684150	2834.64038086	0.06233191
0.18733375	2833.62060547	0.06268016
0.18783085	2832.51391602	0.06302792
0.18833537	2833.50000000	0.06338853
0.18883991	2834.26391602	0.06376204
0.18933949	2833.24804687	0.06412467
0.18984401	2833.80029297	0.06448197
0.19034116	2833.38891602	0.06484100
0.19083583	2831.98999023	0.06520778
0.19132803	2830.95947266	0.06556869
0.19182518	2830.80126953	0.06585139
0.19233708	2831.47680664	0.06623438
0.19284157	2831.96850586	0.06658822
0.19333872	2832.17358398	0.06697097
0.19384325	2832.00073242	0.06734121
0.19433792	2830.92993164	0.06770998
0.19483507	2830.68212891	0.06807685
0.19532974	2829.08496094	0.06844386
0.19583179	2829.61157227	0.06882441
0.19633874	2830.60180664	0.06919727
0.19684081	2829.94116211	0.06957230
0.19734533	2830.22778320	0.06994897
0.19784495	2830.51196289	0.07032356
0.19833468	2827.97680664	0.07068616
0.19882935	2827.56274414	0.07106599
0.19932650	2827.72216797	0.07144010
0.19983840	2827.63916016	0.07182208
0.20034537	2828.81811523	0.07219994
0.20084251	2828.81274414	0.07258320
0.20134456	2828.06640625	0.07297179
0.20183924	2827.53173828	0.07335609
0.20233391	2826.23217773	0.07373586
0.20283106	2825.23925781	0.07411763
0.20333311	2825.44555664	0.07442912
0.20383763	2826.93701172	0.07482398
0.20434217	2826.18261719	0.07522199
0.20483927	2825.65991211	0.07561249
0.20534380	2825.69604492	0.07598495
0.20583600	2823.81347656	0.07637674
0.20633067	2823.12329102	0.07676134
0.20682782	2823.19702148	0.07716268
0.20733234	2823.05102539	0.07754907
0.20784424	2824.41381836	0.07795587
0.20834135	2823.80395508	0.07835761
0.20884345	2823.38745117	0.07874158
0.20934056	2822.99194336	0.07914504
0.20983523	2822.10888672	0.07954496
0.21033238	2820.36035156	0.07994157
0.21083196	2821.03833008	0.08033544
0.21133895	2822.25097656	0.08073586
0.21184100	2821.28491211	0.08111665
0.21234554	2821.32910156	0.08151951
0.21284264	2821.03173828	0.08192092
0.21333489	2819.16381836	0.08233100
0.21382956	2818.76049805	0.08272380
0.21432422	2818.20556641	0.08313027
0.21483614	2819.17724609	0.08352795
0.21534309	2819.32177734	0.08394247
0.21584024	2818.88769531	0.08434477
0.21634477	2818.55810547	0.08476213
0.21683945	2817.26245117	0.08517498
0.21733412	2817.13232422	0.08557400
0.21783122	2815.22827148	0.08599263
0.21833327	2815.91430664	0.08639711
0.21883780	2816.59912109	0.08681300
0.21933985	2815.45483398	0.08722609
0.21984190	2816.06176758	0.08763871
0.22034401	2815.83789062	0.08806312
0.22083619	2813.62426758	0.08848622
0.22132839	2813.02661133	0.08889502
0.22182801	2812.87792969	0.08932066
0.22233745	2813.17285156	0.08973509
0.22284441	2813.59082031	0.09015802
0.22334155	2813.25585937	0.09059262
0.22384113	2812.65161133	0.09101382
0.22434075	2812.02441406	0.09144691
0.22483295	2811.53540039	0.09186733
0.22533010	2809.49853516	0.09229276
0.22583216	2809.58959961	0.09263328
0.22633669	2810.57177734	0.09306708
0.22684121	2810.03320312	0.09350187
0.22734326	2809.89794922	0.09394300
0.22784284	2809.40356445	0.09437376
0.22833504	2807.47924805	0.09481391
0.22882971	2806.89501953	0.09525070
0.22932933	2806.41259766	0.09569111
0.22983877	2807.59179687	0.09611994
0.23034330	2807.24755859	0.09655902
0.23084040	2806.90576172	0.09701020
0.23134492	2806.23852539	0.09744439
0.23183960	2805.35668945	0.09787786
0.23233674	2805.26708984	0.09832036
0.23283389	2803.20483398	0.09876814
0.23333347	2802.87255859	0.09920776
0.23383801	2804.01538086	0.09966201
0.23434006	2802.80273437	0.10010758
0.23484458	2803.09350586	0.10055649
0.23534416	2802.64868164	0.10099816
0.23583636	2800.65478516	0.10144880
0.23633103	2799.87622070	0.10189930
0.23682570	2799.39257812	0.10234246
0.23733519	2800.06665039	0.10280499
0.23784214	2800.30371094	0.10325354
0.23834176	2799.58154297	0.10371286
0.23884624	2798.82568359	0.10416180
0.23933849	2798.04443359	0.10461885
0.23983559	2797.35302734	0.10507977
0.24033274	2795.56689453	0.10552964
0.24083236	2795.27075195	0.10598186
0.24133933	2796.46337891	0.10644695
0.24184138	2795.31494141	0.10690475
0.24234590	2795.59375000	0.10736752
0.24284305	2794.68798828	0.10782498
0.24333525	2792.18896484	0.10828260
0.24382992	2791.26831055	0.10875443
0.24432707	2791.11035156	0.10921353
0.24483649	2791.35546875	0.10967642
0.24534346	2791.58593750	0.11014602
0.24584308	2790.92138672	0.11060113
0.24634266	2790.20971680	0.11107332
0.24684228	2789.08154297	0.11154866
0.24733448	2788.51196289	0.11199546
0.24783406	2786.69360352	0.11247593
0.24833611	2786.69897461	0.11294016
0.24883573	2786.14965820	0.11341688
0.24934027	2786.08813477	0.11389035
0.24984474	2786.05712891	0.11436799
0.25034189	2785.14477539	0.11483195
0.25083655	2782.43383789	0.11531392
0.25132877	2781.41284180	0.11579436
0.25182590	2781.02563477	0.11625460
0.25234029	2781.32055664	0.11673605
0.25284234	2781.68627930	0.11721256
0.25334191	2781.09252930	0.11769360
0.25384396	2779.81420898	0.11816102
0.25434113	2778.71411133	0.11864606
0.25483578	2778.09521484	0.11912251
0.25533295	2776.29956055	0.11960575
0.25583252	2775.45410156	0.12007770
0.25633705	2775.82519531	0.12055862
0.25683910	2774.45043945	0.12104565
0.25734115	2774.92480469	0.12151667
0.25784320	2774.20800781	0.12200186
0.25833541	2771.11132812	0.12248513
0.25883013	2770.31933594	0.12296626
0.25932479	2769.45361328	0.12343702
0.25983423	2769.65063477	0.12388361
0.26034120	2770.25488281	0.12436363
0.26084080	2768.82519531	0.12486234
0.26134530	2767.68090820	0.12534639
0.26184243	2767.23876953	0.12582996
0.26233464	2765.90283203	0.12631333
0.26283178	2763.51635742	0.12680390
0.26333383	2762.90405273	0.12729359
0.26383838	2763.81250000	0.12775788
0.26434538	2762.85424805	0.12826198
0.26484495	2761.95922852	0.12875175
0.26534209	2761.04541016	0.12924343
0.26583678	2758.53564453	0.12973410
0.26633143	2756.85253906	0.13021019
0.26682612	2756.02587891	0.13069868
0.26733556	2755.81152344	0.13119096
0.26784250	2756.56445312	0.13167122
0.26834455	2755.33837891	0.13215384
0.26884171	2753.53344727	0.13265553
0.26934132	2752.67871094	0.13316739
0.26983601	2751.46997070	0.13362607
0.27033311	2749.44262695	0.13412651
0.27083516	2748.93334961	0.13461804
0.27133721	2748.50195312	0.13510597
0.27184173	2747.23852539	0.13560089
0.27234378	2747.15136719	0.13609675
0.27284342	2746.18115234	0.13659415
0.27333808	2742.97607422	0.13708735
0.27383029	2741.45922852	0.13757586
0.27432495	2740.73022461	0.13807741
0.27483439	2739.79492187	0.13856986
0.27534384	2740.17016602	0.13906252
0.27584344	2739.25097656	0.13955879
0.27634302	2737.44189453	0.14005452
0.27684018	2735.86206055	0.14055797
0.27733484	2734.81689453	0.14104822
0.27783442	2733.15136719	0.14153892
0.27833405	2731.43627930	0.14203435
0.27883857	2731.37060547	0.14254388
0.27934062	2729.88720703	0.14301544
0.27984512	2729.68359375	0.14351705
0.28034472	2728.16528320	0.14402398
0.28083450	2725.12890625	0.14451584
0.28132918	2723.74340820	0.14499947
0.28182629	2722.45971680	0.14551124
0.28233570	2721.83007812	0.14600268
0.28284273	2721.96264648	0.14650118
0.28333986	2720.55834961	0.14700311
0.28384435	2718.41040039	0.14749515
0.28434148	2717.12402344	0.14798972
0.28483617	2715.69433594	0.14848784
0.28533331	2713.22607422	0.14898711
0.28583288	2711.80444336	0.14947885
0.28633741	2711.85668945	0.14988342
0.28683946	2710.05712891	0.15040100
0.28734401	2709.50756836	0.15089330
0.28784359	2708.28149414	0.15139881
0.28833583	2705.13940430	0.15189064
0.28882802	2702.98999023	0.15239009
0.28932518	2701.30981445	0.15290061
0.28983459	2700.91186523	0.15339357
0.29034403	2700.92382812	0.15389869
0.29084361	2699.50341797	0.15440407
0.29134324	2697.00439453	0.15489006
0.29184037	2695.51025391	0.15539092
0.29233506	2693.90917969	0.15590408
0.29283217	2691.19165039	0.15640366
0.29333422	2689.91455078	0.15689439
0.29383874	2689.77807617	0.15740550
0.29434079	2687.53076172	0.15791056
0.29484284	2686.93334961	0.15840900
0.29534248	2685.75415039	0.15891451
0.29583713	2682.54492187	0.15941712
0.29633182	2679.96142578	0.15991139
0.29682648	2678.14575195	0.16040710
0.29733345	2677.40478516	0.16091871
0.29784286	2677.33105469	0.16143018
0.29834002	2674.90161133	0.16193008
0.29884455	2673.30712891	0.16241959
0.29933923	2671.02661133	0.16292652
0.29983637	2669.34887695	0.16342792
0.30033347	2666.66894531	0.16392639
0.30083063	2665.07177734	0.16443089
0.30133763	2664.55859375	0.16494840
0.30183968	2661.62792969	0.16543773
0.30234420	2661.88403320	0.16596252
0.30284625	2660.22900391	0.16646436
0.30333847	2656.36450195	0.16695058
0.30383065	2653.44482422	0.16745585
0.30432531	2652.09155273	0.16795713
0.30483475	2650.54101562	0.16846660
0.30534422	2650.26098633	0.16897246
0.30584133	2649.26000977	0.16948241
0.30634338	2645.86718750	0.17000535
0.30684054	2643.43530273	0.17048684
0.30733520	2641.52587891	0.17099723
0.30783236	2639.13134766	0.17150250
0.30833194	2637.05712891	0.17201579
0.30883893	2636.06152344	0.17252290
0.30934098	2633.97387695	0.17303565
0.30984551	2633.10668945	0.17353317
0.31034261	2630.49926758	0.17404512
0.31083730	2627.06494141	0.17454559
0.31132954	2624.56445312	0.17505172
0.31182665	2622.17675781	0.17556566
0.31233612	2621.10742187	0.17606685
0.31284061	2620.64501953	0.17655653
0.31334022	2618.30810547	0.17706472
0.31384474	2615.31201172	0.17758688
0.31434184	2612.79296875	0.17808470
0.31483653	2610.73608398	0.17859364
0.31533119	2607.64477539	0.17909992
0.31583324	2605.55444336	0.17960551
0.31634027	2604.76245117	0.18011722
0.31683984	2601.36303711	0.18063068
0.31734437	2600.10205078	0.18113926
0.31784397	2598.35205078	0.18164626
0.31833619	2595.05444336	0.18216270
0.31883085	2591.45385742	0.18266398
0.31932554	2588.82885742	0.18316418
0.31983247	2587.40185547	0.18367440
0.32034197	2586.97045898	0.18418574
0.32083908	2584.33349609	0.18470755
0.32134113	2581.36010742	0.18521926
0.32184073	2578.55004883	0.18572420
0.32233542	2576.15283203	0.18622276
0.32283252	2572.49877930	0.18673009
0.32332966	2570.19799805	0.18724671
0.32383668	2569.30688477	0.18775058
0.32434115	2566.27856445	0.18827662
0.32484326	2564.65454102	0.18877289
0.32534283	2562.54418945	0.18929133
0.32583997	2559.00000000	0.18978804
0.32633218	2554.71215820	0.19030017
0.32682684	2552.34448242	0.19079790
0.32733381	2550.35986328	0.19132945
0.32784081	2549.31616211	0.19184554
0.32834285	2547.24316406	0.19234186
0.32884243	2543.80200195	0.19284970
0.32934207	2540.40795898	0.19336072
0.32983673	2537.52563477	0.19388115
0.33033141	2533.43603516	0.19437683
0.33083346	2531.89111328	0.19487473
0.33134043	2529.70703125	0.19540325
0.33184004	2526.58886719	0.19591522
0.33234701	2524.87915039	0.19642603
0.33284166	2521.97802734	0.19691640
0.33333883	2517.78808594	0.19744420
0.33383101	2514.58276367	0.19794285
0.33432570	2511.58520508	0.19845897
0.33483517	2509.36352539	0.19897163
0.33534214	2507.64306641	0.19948599
0.33584172	2505.27539062	0.20000139
0.33634380	2501.45239258	0.20051762
0.33684090	2497.74340820	0.20102987
0.33733559	2494.99243164	0.20153052
0.33783272	2491.27539062	0.20205688
0.33833230	2488.28735352	0.20258063
0.33883929	2485.94628906	0.20306489
0.33934137	2482.74243164	0.20358914
0.33984342	2480.02905273	0.20410043
0.34034547	2477.70166016	0.20460787
0.34083772	2472.66601562	0.20511705
0.34132990	2469.11376953	0.20563579
0.34182706	2465.53735352	0.20615232
0.34233400	2462.60009766	0.20666566
0.34284344	2461.85107422	0.20716605
0.34334061	2458.21704102	0.20767817
0.34384266	2454.52954102	0.20820117
0.34434223	2450.95996094	0.20871577
0.34483448	2447.37670898	0.20916829
0.34533158	2442.84497070	0.20967695
0.34583366	2440.34057617	0.21019056
0.34633815	2437.91137695	0.21069849
0.34684020	2433.64477539	0.21121487
0.34734473	2430.88720703	0.21173537
0.34784436	2427.90844727	0.21226189
0.34833902	2423.42626953	0.21278000
0.34883124	2418.79931641	0.21328878
0.34932590	2414.67236328	0.21380249
0.34983286	2412.05126953	0.21433949
0.35034233	2409.88989258	0.21485221
0.35083944	2406.53320312	0.21536243
0.35134149	2402.71435547	0.21587512
0.35183865	2398.88623047	0.21640903
0.35233578	2394.24707031	0.21691704
0.35283047	2389.75292969	0.21742517
0.35333005	2386.65356445	0.21794593
0.35383704	2384.11303711	0.21846968
0.35433909	2379.47265625	0.21899229
0.35484362	2376.02099609	0.21951139
0.35534567	2373.25390625	0.22003675
0.35583788	2368.06420898	0.22054231
0.35633254	2362.81958008	0.22106090
0.35682723	2359.40942383	0.22157797
0.35733423	2355.48999023	0.22209200
0.35784611	2353.20141602	0.22263089
0.35834080	2349.48413086	0.22314614
0.35884285	2344.98071289	0.22366047
0.35934243	2340.48632812	0.22418934
0.35983464	2335.42260742	0.22469923
0.36033177	2330.79833984	0.22523516
0.36083135	2327.03173828	0.22574079
0.36133835	2324.34643555	0.22627720
0.36184040	2319.29760742	0.22678208
0.36233997	2315.24804687	0.22730181
0.36284453	2311.37036133	0.22783989
0.36333677	2305.60449219	0.22836971
0.36383143	2301.46264648	0.22887039
0.36432609	2296.48999023	0.22940516
0.36483058	2291.90063477	0.22992057
0.36534250	2289.81030273	0.23044506
0.36584210	2285.78369141	0.23097241
0.36634168	2280.35937500	0.23150092
0.36684376	2275.38012695	0.23203745
0.36733595	2270.26684570	0.23255011
0.36783308	2264.78100586	0.23308054
0.36833271	2260.36572266	0.23358834
0.36883721	2257.13525391	0.23412639
0.36934173	2252.08618164	0.23465961
0.36984378	2247.33593750	0.23518559
0.37034339	2242.96630859	0.23571360
0.37083808	2236.90966797	0.23622131
0.37133026	2231.67456055	0.23674572
0.37182495	2226.36694336	0.23729175
0.37233439	2221.83374023	0.23782855
0.37284380	2218.80932617	0.23833919
0.37334096	2213.45629883	0.23888668
0.37384549	2208.00927734	0.23940557
0.37434015	2202.49804687	0.23992291
0.37483731	2197.04028320	0.24046206
0.37533197	2190.63134766	0.24099779
0.37583154	2186.14233398	0.24154478
0.37633857	2182.47900391	0.24204677
0.37683815	2176.52539062	0.24258700
0.37734267	2170.70874023	0.24311012
0.37784472	2166.22656250	0.24365309
0.37833691	2159.53735352	0.24418351
0.37883160	2153.32788086	0.24473605
0.37932625	2147.89697266	0.24525395
0.37983328	2142.75830078	0.24578539
0.38034269	2138.51733398	0.24632522
0.38084227	2132.58520508	0.24685657
0.38134190	2126.50195312	0.24738044
0.38184148	2120.78295898	0.24794191
0.38233614	2113.87792969	0.24847913
0.38283330	2107.69018555	0.24897718
0.38333288	2101.55981445	0.24953023
0.38383740	2097.27709961	0.25007224
0.38433945	2090.43945312	0.25062206
0.38484150	2084.66015625	0.25117376
0.38534114	2078.97460937	0.25169736
0.38583824	2071.08764648	0.25221205
0.38633049	2064.24829102	0.25275156
0.38682759	2058.41821289	0.25329188
0.38733459	2051.74389648	0.25384471
0.38784155	2046.39062500	0.25438842
0.38834116	2040.49206543	0.25493005
0.38884321	2033.02990723	0.25547609
0.38934031	2026.17321777	0.25602925
0.38983747	2018.92944336	0.25655013
0.39033213	2010.40588379	0.25712845
0.39083177	2003.88159180	0.25766143
0.39133871	1997.95361328	0.25820431
0.39183834	1989.65649414	0.25875238
0.39234531	1982.28405762	0.25930002
0.39284489	1971.83630371	0.25988165
0.39333954	1902.93249512	0.26084247
0.39381456	716.21984863	0.27277032
0.39378259	629.80676270	0.27408764