File: test1_sample_c_group 6
%	Crosshead Position (in)	Load (lbs)	Extensometer Position (in)	3/6/2017	3:18 PM
0.00015501	8.53022385	-0.01491699
0.00064230	82.35832977	-0.01484686
0.00114435	148.67457581	-0.01482460
0.00164645	209.01861572	-0.01476321
0.00214113	257.25201416	-0.01472932
0.00263823	307.76336670	-0.01471826
0.00313290	358.10455322	-0.01466495
0.00363495	403.80276489	-0.01464091
0.00413948	447.38247681	-0.01461871
0.00464153	486.08740234	-0.01458880
0.00514606	519.76745605	-0.01457536
0.00564564	551.39331055	-0.01455376
0.00613788	579.56744385	-0.01453468
0.00663008	601.39147949	-0.01450874
0.00712966	627.23541260	-0.01448940
0.00763914	650.66601562	-0.01445764
0.00814362	674.28558350	-0.01444562
0.00864572	696.68713379	-0.01442336
0.00914529	717.82379150	-0.01440564
0.00964244	736.35284424	-0.01440115
0.01013464	756.49383545	-0.01439524
0.01063422	778.13299561	-0.01437511
0.01113875	799.19726562	-0.01437320
0.01163837	820.79882812	-0.01434986
0.01214042	842.61346436	-0.01432991
0.01264490	864.00872803	-0.01431885
0.01314453	886.14361572	-0.01430170
0.01363920	907.90332031	-0.01428901
0.01413140	928.83624268	-0.01426969
0.01462855	951.56878662	-0.01425797
0.01513798	976.25097656	-0.01424320
0.01564251	998.79858398	-0.01422952
0.01614209	1022.05902100	-0.01420400
0.01664414	1046.05114746	-0.01419337
0.01714128	1067.45837402	-0.01416442
0.01763596	1090.59289551	-0.01415724
0.01813311	1114.42687988	-0.01413874
0.01863268	1137.97412109	-0.01412563
0.01913969	1162.69787598	-0.01409790
0.01964174	1187.67346191	-0.01407671
0.02014627	1211.10949707	-0.01406924
0.02064832	1235.74072266	-0.01403417
0.02113804	1259.62426758	-0.01401587
0.02163272	1282.26171875	-0.01399964
0.02212987	1306.79907227	-0.01398608
0.02263930	1332.72204590	-0.01395734
0.02314630	1358.00463867	-0.01393533
0.02364340	1382.62243652	-0.01390834
0.02414550	1408.00134277	-0.01388608
0.02464017	1431.05151367	-0.01386973
0.02513485	1455.36511230	-0.01385498
0.02563442	1480.55383301	-0.01381961
0.02613648	1504.97473145	-0.01378712
0.02664101	1530.94995117	-0.01378848
0.02714306	1555.90417480	-0.01374952
0.02764264	1579.48889160	-0.01372756
0.02814469	1604.80358887	-0.01369588
0.02863936	1628.51159668	-0.01367217
0.02913160	1651.93554687	-0.01364206
0.02962871	1675.17590332	-0.01363014
0.03013323	1700.19836426	-0.01360609
0.03064514	1724.91674805	-0.01357165
0.03114477	1748.82971191	-0.01353425
0.03164434	1772.35693359	-0.01350865
0.03214392	1792.93212891	-0.01347779
0.03263617	1814.09948730	-0.01345012
0.03313574	1836.21166992	-0.01342981
0.03363532	1857.58813477	-0.01339009
0.03413985	1880.69445801	-0.01335767
0.03464438	1902.89904785	-0.01332510
0.03514643	1924.08129883	-0.01329632
0.03564605	1945.38671875	-0.01326589
0.03613825	1966.25671387	-0.01322481
0.03663292	1985.61376953	-0.01318602
0.03712760	2006.95275879	-0.01315282
0.03763950	2030.12341309	-0.01311268
0.03814646	2051.40478516	-0.01306947
0.03864361	2072.23999023	-0.01302031
0.03914566	2094.34814453	-0.01297626
0.03964033	2112.11474609	-0.01292321
0.04013748	2132.54638672	-0.01287411
0.04063215	2152.84814453	-0.01282811
0.04113421	2172.00708008	-0.01277445
0.04164116	2193.25219727	-0.01272348
0.04214079	2213.56347656	-0.01265675
0.04264532	2231.95581055	-0.01258902
0.04314737	2251.24877930	-0.01253153
0.04363709	2268.58911133	-0.01246417
0.04413177	2286.29418945	-0.01239036
0.04462891	2304.59399414	-0.01231842
0.04513834	2323.98461914	-0.01224488
0.04564535	2341.90136719	-0.01217124
0.04614245	2356.49902344	-0.01208930
0.04664455	2377.11694336	-0.01201044
0.04714165	2393.39086914	-0.01191428
0.04763633	2406.35498047	-0.01181312
0.04813347	2426.62744141	-0.01172733
0.04863553	2442.12011719	-0.01162727
0.04914005	2407.32934570	-0.01157501
0.04964210	2462.77441406	-0.01151557
0.05014416	2484.26342773	-0.01139407
0.05064373	2498.13745117	-0.01125844
0.05113841	2513.48803711	-0.01114067
0.05163308	2528.15527344	-0.01102470
0.05213023	2542.88012695	-0.01089868
0.05263966	2522.79956055	-0.01084037
0.05314419	2567.90673828	-0.01075095
0.05364382	2582.19750977	-0.01061928
0.05414587	2595.74047852	-0.01048534
0.05464054	2608.19555664	-0.01034378
0.05513764	2621.23608398	-0.01020512
0.05563479	2634.41601562	-0.01007159
0.05613441	2647.20190430	-0.00993130
0.05664137	2661.86914062	-0.00980672
0.05714095	2659.68774414	-0.00977455
0.05764548	2684.06445312	-0.00964761
0.05814510	2693.77246094	-0.00948861
0.05863977	2704.47607422	-0.00934017
0.05913197	2714.84741211	-0.00918858
0.05962665	2726.85742187	-0.00903942
0.06013855	2740.56127930	-0.00888677
0.06064551	2751.88012695	-0.00872418
0.06114513	2763.34741211	-0.00859554
0.06164718	2775.39648437	-0.00844876
0.06214186	2739.44116211	-0.00836858
0.06263653	2784.71459961	-0.00827558
0.06305246	-2.83938742	-0.00139433
0.06304014	-3.05110216	-0.00139849